Workbook
Name Bills: Patient_Data!$K$2:$K$41
Name Department: Patient_Data!$E$2:$E$41

Sheet Patient_Data
A1: Patient_ID | B1: Patient_Name | C1: Age | D1: Gender | E1: Department | F1: Diagnosis | G1: Admission_Date | H1: Discharge_Date | I1: Doctor | J1: Insurance_Type | K1: Bill_Amount | L1: Payment_Status | M1: Length_of_Stay | N1: Payment Alert | O1: Bill Category | P1: Age Category | Q1: Case | R1: Follow-up | S1: Dept Priority | T1: Status Payment | U1: Bill Category using SWITCH | V1: Bill Category using NESTEDIF | W1: Financial Risk | X1: Management Review
A2: P1001 | B2: Aarav Sharma | C2: 34 | D2: Male | E2: Cardiology | F2: Hypertension | G2: 46027 | H2: 46030 | I2: Dr Rao | J2: Private Insurance | K2: 18500 | L2: Paid | M2: 3 | N2: =IF(L2="Pending","follow Up","No Action") -> No Action | O2: =IF(K2>40000,"high Bill","Normal Bill") -> Normal Bill | P2: =IF(C2>=60,"Senior Citizen","Non- Senior") -> Non- Senior | Q2: =IF(AND(K2>40000,M2>5),"High Billing Case","Not a High Billing Case") -> Not a High Billing Case | R2: =IF(AND(Patient_Data!L2="Pending",Patient_Data!K2>30000),"Urgent Patient Follow-up","Follow-up not Required") -> Follow-up not Required | S2: =IF(OR(Patient_Data!E2="Cardiology",Patient_Data!E2="Neurology"),"Priority Dept","RegularDept") -> Priority Dept | T2: =IF(NOT(Patient_Data!L2="pending"),"Payment Completed","Payment Pending") -> Payment Completed | U2: {=_xlfn.SWITCH(TRUE,K2>=50000,"Very High",K2>=30000,"High",K2>=15000,"Medium",K2<15000,"Low")} -> Medium | V2: =IF(K2>=50000,"VH",IF(K2>=30000,"High",IF(K2>=15000,"medium","Low"))) -> medium | W2: =IF(AND(Patient_Data!K2>40000,Patient_Data!L2="Pending"),"high Financial Risk","Normal") -> Normal | X2: =IF(AND(K2>30000,OR(E2="Cardiology",E2="Orthopedics")),"MR","No Review") -> No Review
A3: P1002 | B3: Diya Patel | C3: 52 | D3: Female | E3: Orthopedics | F3: Fracture | G3: 46029 | H3: 46037 | I3: Dr Mehta | J3: Government | K3: 42000 | L3: Paid | M3: 8 | N3: =IF(L3="Pending","follow Up","No Action") -> No Action | O3: =IF(K3>40000,"high Bill","Normal Bill") -> high Bill | P3: =IF(C3>=60,"Senior Citizen","Non- Senior") -> Non- Senior | Q3: =IF(AND(K3>40000,M3>5),"High Billing Case","Not a High Billing Case") -> High Billing Case | R3: =IF(AND(Patient_Data!L3="Pending",Patient_Data!K3>30000),"Urgent Patient Follow-up","Follow-up not Required") -> Follow-up not Required | S3: =IF(OR(Patient_Data!E3="Cardiology",Patient_Data!E3="Neurology"),"Priority Dept","RegularDept") -> RegularDept | T3: =IF(NOT(Patient_Data!L3="pending"),"Payment Completed","Payment Pending") -> Payment Completed | U3: {=_xlfn.SWITCH(TRUE,K3>=50000,"VH",K3>=30000,"High",K3>=15000,"Medium",K3<15000,"Low")} -> High | V3: =IF(K3>=50000,"VH",IF(K3>=30000,"High",IF(K3>=15000,"medium","Low"))) -> High | W3: =IF(AND(Patient_Data!K3>40000,Patient_Data!L3="Pending"),"high Financial Risk","Normal") -> Normal | X3: =IF(AND(K3>30000,OR(E3="Cardiology",E3="Orthopedics")),"MR","No Review") -> MR
A4: P1003 | B4: Rohan Kumar | C4: 28 | D4: Male | E4: General Medicine | F4: Diabetes | G4: 46032 | H4: 46035 | I4: Dr Singh | J4: Private Insurance | K4: 12000 | L4: Paid | M4: 3 | N4: =IF(L4="Pending","follow Up","No Action") -> No Action | O4: =IF(K4>40000,"high Bill","Normal Bill") -> Normal Bill | P4: =IF(C4>=60,"Senior Citizen","Non- Senior") -> Non- Senior | Q4: =IF(AND(K4>40000,M4>5),"High Billing Case","Not a High Billing Case") -> Not a High Billing Case | R4: =IF(AND(Patient_Data!L4="Pending",Patient_Data!K4>30000),"Urgent Patient Follow-up","Follow-up not Required") -> Follow-up not Required | S4: =IF(OR(Patient_Data!E4="Cardiology",Patient_Data!E4="Neurology"),"Priority Dept","RegularDept") -> RegularDept | T4: =IF(NOT(Patient_Data!L4="pending"),"Payment Completed","Payment Pending") -> Payment Completed | U4: {=_xlfn.SWITCH(TRUE,K4>=50000,"VH",K4>=30000,"High",K4>=15000,"Medium",K4<15000,"Low")} -> Low | V4: =IF(K4>=50000,"VH",IF(K4>=30000,"High",IF(K4>=15000,"medium","Low"))) -> Low | W4: =IF(AND(Patient_Data!K4>40000,Patient_Data!L4="Pending"),"high Financial Risk","Normal") -> Normal | X4: =IF(AND(K4>30000,OR(E4="Cardiology",E4="Orthopedics")),"MR","No Review") -> No Review
A5: P1004 | B5: Ananya Reddy | C5: 45 | D5: Female | E5: Cardiology | F5: Chest Pain | G5: 46034 | H5: 46039 | I5: Dr Rao | J5: Self Pay | K5: 27500 | L5: Pending | M5: 5 | N5: =IF(L5="Pending","follow Up","No Action") -> follow Up | O5: =IF(K5>40000,"high Bill","Normal Bill") -> Normal Bill | P5: =IF(C5>=60,"Senior Citizen","Non- Senior") -> Non- Senior | Q5: =IF(AND(K5>40000,M5>5),"High Billing Case","Not a High Billing Case") -> Not a High Billing Case | R5: =IF(AND(Patient_Data!L5="Pending",Patient_Data!K5>30000),"Urgent Patient Follow-up","Follow-up not Required") -> Follow-up not Required | S5: =IF(OR(Patient_Data!E5="Cardiology",Patient_Data!E5="Neurology"),"Priority Dept","RegularDept") -> Priority Dept | T5: =IF(NOT(Patient_Data!L5="pending"),"Payment Completed","Payment Pending") -> Payment Pending | U5: {=_xlfn.SWITCH(TRUE,K5>=50000,"VH",K5>=30000,"High",K5>=15000,"Medium",K5<15000,"Low")} -> Medium | V5: =IF(K5>=50000,"VH",IF(K5>=30000,"High",IF(K5>=15000,"medium","Low"))) -> medium | W5: =IF(AND(Patient_Data!K5>40000,Patient_Data!L5="Pending"),"high Financial Risk","Normal") -> Normal | X5: =IF(AND(K5>30000,OR(E5="Cardiology",E5="Orthopedics")),"MR","No Review") -> No Review
A6: P1005 | B6: Vikram Singh | C6: 67 | D6: Male | E6: Neurology | F6: Migraine | G6: 46037 | H6: 46040 | I6: Dr Khan | J6: Government | K6: 16000 | L6: Paid | M6: 3 | N6: =IF(L6="Pending","follow Up","No Action") -> No Action | O6: =IF(K6>40000,"high Bill","Normal Bill") -> Normal Bill | P6: =IF(C6>=60,"Senior Citizen","Non- Senior") -> Senior Citizen | Q6: =IF(AND(K6>40000,M6>5),"High Billing Case","Not a High Billing Case") -> Not a High Billing Case | R6: =IF(AND(Patient_Data!L6="Pending",Patient_Data!K6>30000),"Urgent Patient Follow-up","Follow-up not Required") -> Follow-up not Required | S6: =IF(OR(Patient_Data!E6="Cardiology",Patient_Data!E6="Neurology"),"Priority Dept","RegularDept") -> Priority Dept | T6: =IF(NOT(Patient_Data!L6="pending"),"Payment Completed","Payment Pending") -> Payment Completed | U6: {=_xlfn.SWITCH(TRUE,K6>=50000,"VH",K6>=30000,"High",K6>=15000,"Medium",K6<15000,"Low")} -> Medium | V6: =IF(K6>=50000,"VH",IF(K6>=30000,"High",IF(K6>=15000,"medium","Low"))) -> medium | W6: =IF(AND(Patient_Data!K6>40000,Patient_Data!L6="Pending"),"high Financial Risk","Normal") -> Normal | X6: =IF(AND(K6>30000,OR(E6="Cardiology",E6="Orthopedics")),"MR","No Review") -> No Review
A7: P1006 | B7: Meera Nair | C7: 39 | D7: Female | E7: General Medicine | F7: Asthma | G7: 46040 | H7: 46042 | I7: Dr Singh | J7: Private Insurance | K7: 9500 | L7: Paid | M7: 2 | N7: =IF(L7="Pending","follow Up","No Action") -> No Action | O7: =IF(K7>40000,"high Bill","Normal Bill") -> Normal Bill | P7: =IF(C7>=60,"Senior Citizen","Non- Senior") -> Non- Senior | Q7: =IF(AND(K7>40000,M7>5),"High Billing Case","Not a High Billing Case") -> Not a High Billing Case | R7: =IF(AND(Patient_Data!L7="Pending",Patient_Data!K7>30000),"Urgent Patient Follow-up","Follow-up not Required") -> Follow-up not Required | S7: =IF(OR(Patient_Data!E7="Cardiology",Patient_Data!E7="Neurology"),"Priority Dept","RegularDept") -> RegularDept | T7: =IF(NOT(Patient_Data!L7="pending"),"Payment Completed","Payment Pending") -> Payment Completed | U7: {=_xlfn.SWITCH(TRUE,K7>=50000,"VH",K7>=30000,"High",K7>=15000,"Medium",K7<15000,"Low")} -> Low | V7: =IF(K7>=50000,"VH",IF(K7>=30000,"High",IF(K7>=15000,"medium","Low"))) -> Low | W7: =IF(AND(Patient_Data!K7>40000,Patient_Data!L7="Pending"),"high Financial Risk","Normal") -> Normal | X7: =IF(AND(K7>30000,OR(E7="Cardiology",E7="Orthopedics")),"MR","No Review") -> No Review
A8: P1007 | B8: Arjun Verma | C8: 73 | D8: Male | E8: Cardiology | F8: Heart Disease | G8: 46042 | H8: 46051 | I8: Dr Rao | J8: Government | K8: 68000 | L8: Pending | M8: 9 | N8: =IF(L8="Pending","follow Up","No Action") -> follow Up | O8: =IF(K8>40000,"high Bill","Normal Bill") -> high Bill | P8: =IF(C8>=60,"Senior Citizen","Non- Senior") -> Senior Citizen | Q8: =IF(AND(K8>40000,M8>5),"High Billing Case","Not a High Billing Case") -> High Billing Case | R8: =IF(AND(Patient_Data!L8="Pending",Patient_Data!K8>30000),"Urgent Patient Follow-up","Follow-up not Required") -> Urgent Patient Follow-up | S8: =IF(OR(Patient_Data!E8="Cardiology",Patient_Data!E8="Neurology"),"Priority Dept","RegularDept") -> Priority Dept | T8: =IF(NOT(Patient_Data!L8="pending"),"Payment Completed","Payment Pending") -> Payment Pending | U8: {=_xlfn.SWITCH(TRUE,K8>=50000,"VH",K8>=30000,"High",K8>=15000,"Medium",K8<15000,"Low")} -> VH | V8: =IF(K8>=50000,"VH",IF(K8>=30000,"High",IF(K8>=15000,"medium","Low"))) -> VH | W8: =IF(AND(Patient_Data!K8>40000,Patient_Data!L8="Pending"),"high Financial Risk","Normal") -> high Financial Risk | X8: =IF(AND(K8>30000,OR(E8="Cardiology",E8="Orthopedics")),"MR","No Review") -> MR
A9: P1008 | B9: Sneha Iyer | C9: 31 | D9: Female | E9: Dermatology | F9: Skin Allergy | G9: 46044 | H9: 46046 | I9: Dr Thomas | J9: Self Pay | K9: 7500 | L9: Paid | M9: 2 | N9: =IF(L9="Pending","follow Up","No Action") -> No Action | O9: =IF(K9>40000,"high Bill","Normal Bill") -> Normal Bill | P9: =IF(C9>=60,"Senior Citizen","Non- Senior") -> Non- Senior | Q9: =IF(AND(K9>40000,M9>5),"High Billing Case","Not a High Billing Case") -> Not a High Billing Case | R9: =IF(AND(Patient_Data!L9="Pending",Patient_Data!K9>30000),"Urgent Patient Follow-up","Follow-up not Required") -> Follow-up not Required | S9: =IF(OR(Patient_Data!E9="Cardiology",Patient_Data!E9="Neurology"),"Priority Dept","RegularDept") -> RegularDept | T9: =IF(NOT(Patient_Data!L9="pending"),"Payment Completed","Payment Pending") -> Payment Completed | U9: {=_xlfn.SWITCH(TRUE,K9>=50000,"VH",K9>=30000,"High",K9>=15000,"Medium",K9<15000,"Low")} -> Low | V9: =IF(K9>=50000,"VH",IF(K9>=30000,"High",IF(K9>=15000,"medium","Low"))) -> Low | W9: =IF(AND(Patient_Data!K9>40000,Patient_Data!L9="Pending"),"high Financial Risk","Normal") -> Normal | X9: =IF(AND(K9>30000,OR(E9="Cardiology",E9="Orthopedics")),"MR","No Review") -> No Review | Z9: "female"
A10: P1009 | B10: Karan Shah | C10: 56 | D10: Male | E10: Orthopedics | F10: Arthritis | G10: 46047 | H10: 46052 | I10: Dr Mehta | J10: Private Insurance | K10: 24000 | L10: Paid | M10: 5 | N10: =IF(L10="Pending","follow Up","No Action") -> No Action | O10: =IF(K10>40000,"high Bill","Normal Bill") -> Normal Bill | P10: =IF(C10>=60,"Senior Citizen","Non- Senior") -> Non- Senior | Q10: =IF(AND(K10>40000,M10>5),"High Billing Case","Not a High Billing Case") -> Not a High Billing Case | R10: =IF(AND(Patient_Data!L10="Pending",Patient_Data!K10>30000),"Urgent Patient Follow-up","Follow-up not Required") -> Follow-up not Required | S10: =IF(OR(Patient_Data!E10="Cardiology",Patient_Data!E10="Neurology"),"Priority Dept","RegularDept") -> RegularDept | T10: =IF(NOT(Patient_Data!L10="pending"),"Payment Completed","Payment Pending") -> Payment Completed | U10: {=_xlfn.SWITCH(TRUE,K10>=50000,"VH",K10>=30000,"High",K10>=15000,"Medium",K10<15000,"Low")} -> Medium | V10: =IF(K10>=50000,"VH",IF(K10>=30000,"High",IF(K10>=15000,"medium","Low"))) -> medium | W10: =IF(AND(Patient_Data!K10>40000,Patient_Data!L10="Pending"),"high Financial Risk","Normal") -> Normal | X10: =IF(AND(K10>30000,OR(E10="Cardiology",E10="Orthopedics")),"MR","No Review") -> No Review
A11: P1010 | B11: Priya Das | C11: 24 | D11: Female | E11: General Medicine | F11: Fever | G11: 46050 | H11: 46052 | I11: Dr Singh | J11: Self Pay | K11: 6500 | L11: Paid | M11: 2 | N11: =IF(L11="Pending","follow Up","No Action") -> No Action | O11: =IF(K11>40000,"high Bill","Normal Bill") -> Normal Bill | P11: =IF(C11>=60,"Senior Citizen","Non- Senior") -> Non- Senior | Q11: =IF(AND(K11>40000,M11>5),"High Billing Case","Not a High Billing Case") -> Not a High Billing Case | R11: =IF(AND(Patient_Data!L11="Pending",Patient_Data!K11>30000),"Urgent Patient Follow-up","Follow-up not Required") -> Follow-up not Required | S11: =IF(OR(Patient_Data!E11="Cardiology",Patient_Data!E11="Neurology"),"Priority Dept","RegularDept") -> RegularDept | T11: =IF(NOT(Patient_Data!L11="pending"),"Payment Completed","Payment Pending") -> Payment Completed | U11: {=_xlfn.SWITCH(TRUE,K11>=50000,"VH",K11>=30000,"High",K11>=15000,"Medium",K11<15000,"Low")} -> Low | V11: =IF(K11>=50000,"VH",IF(K11>=30000,"High",IF(K11>=15000,"medium","Low"))) -> Low | W11: =IF(AND(Patient_Data!K11>40000,Patient_Data!L11="Pending"),"high Financial Risk","Normal") -> Normal | X11: =IF(AND(K11>30000,OR(E11="Cardiology",E11="Orthopedics")),"MR","No Review") -> No Review
A12: P1011 | B12: Aditya Rao | C12: 61 | D12: Male | E12: Cardiology | F12: Hypertension | G12: 46055 | H12: 46059 | I12: Dr Rao | J12: Private Insurance | K12: 22000 | L12: Paid | M12: 4 | N12: =IF(L12="Pending","follow Up","No Action") -> No Action | O12: =IF(K12>40000,"high Bill","Normal Bill") -> Normal Bill | P12: =IF(C12>=60,"Senior Citizen","Non- Senior") -> Senior Citizen | Q12: =IF(AND(K12>40000,M12>5),"High Billing Case","Not a High Billing Case") -> Not a High Billing Case | R12: =IF(AND(Patient_Data!L12="Pending",Patient_Data!K12>30000),"Urgent Patient Follow-up","Follow-up not Required") -> Follow-up not Required | S12: =IF(OR(Patient_Data!E12="Cardiology",Patient_Data!E12="Neurology"),"Priority Dept","RegularDept") -> Priority Dept | T12: =IF(NOT(Patient_Data!L12="pending"),"Payment Completed","Payment Pending") -> Payment Completed | U12: {=_xlfn.SWITCH(TRUE,K12>=50000,"VH",K12>=30000,"High",K12>=15000,"Medium",K12<15000,"Low")} -> Medium | V12: =IF(K12>=50000,"VH",IF(K12>=30000,"High",IF(K12>=15000,"medium","Low"))) -> medium | W12: =IF(AND(Patient_Data!K12>40000,Patient_Data!L12="Pending"),"high Financial Risk","Normal") -> Normal | X12: =IF(AND(K12>30000,OR(E12="Cardiology",E12="Orthopedics")),"MR","No Review") -> No Review
A13: P1012 | B13: Kavya Menon | C13: 48 | D13: Female | E13: Neurology | F13: Seizure Disorder | G13: 46057 | H13: 46064 | I13: Dr Khan | J13: Government | K13: 39000 | L13: Pending | M13: 7 | N13: =IF(L13="Pending","follow Up","No Action") -> follow Up | O13: =IF(K13>40000,"high Bill","Normal Bill") -> Normal Bill | P13: =IF(C13>=60,"Senior Citizen","Non- Senior") -> Non- Senior | Q13: =IF(AND(K13>40000,M13>5),"High Billing Case","Not a High Billing Case") -> Not a High Billing Case | R13: =IF(AND(Patient_Data!L13="Pending",Patient_Data!K13>30000),"Urgent Patient Follow-up","Follow-up not Required") -> Urgent Patient Follow-up | S13: =IF(OR(Patient_Data!E13="Cardiology",Patient_Data!E13="Neurology"),"Priority Dept","RegularDept") -> Priority Dept | T13: =IF(NOT(Patient_Data!L13="pending"),"Payment Completed","Payment Pending") -> Payment Pending | U13: {=_xlfn.SWITCH(TRUE,K13>=50000,"VH",K13>=30000,"High",K13>=15000,"Medium",K13<15000,"Low")} -> High | V13: =IF(K13>=50000,"VH",IF(K13>=30000,"High",IF(K13>=15000,"medium","Low"))) -> High | W13: =IF(AND(Patient_Data!K13>40000,Patient_Data!L13="Pending"),"high Financial Risk","Normal") -> Normal | X13: =IF(AND(K13>30000,OR(E13="Cardiology",E13="Orthopedics")),"MR","No Review") -> No Review
A14: P1013 | B14: Raj Malhotra | C14: 36 | D14: Male | E14: Orthopedics | F14: Back Pain | G14: 46059 | H14: 46062 | I14: Dr Mehta | J14: Self Pay | K14: 14500 | L14: Paid | M14: 3 | N14: =IF(L14="Pending","follow Up","No Action") -> No Action | O14: =IF(K14>40000,"high Bill","Normal Bill") -> Normal Bill | P14: =IF(C14>=60,"Senior Citizen","Non- Senior") -> Non- Senior | Q14: =IF(AND(K14>40000,M14>5),"High Billing Case","Not a High Billing Case") -> Not a High Billing Case | R14: =IF(AND(Patient_Data!L14="Pending",Patient_Data!K14>30000),"Urgent Patient Follow-up","Follow-up not Required") -> Follow-up not Required | S14: =IF(OR(Patient_Data!E14="Cardiology",Patient_Data!E14="Neurology"),"Priority Dept","RegularDept") -> RegularDept | T14: =IF(NOT(Patient_Data!L14="pending"),"Payment Completed","Payment Pending") -> Payment Completed | U14: {=_xlfn.SWITCH(TRUE,K14>=50000,"VH",K14>=30000,"High",K14>=15000,"Medium",K14<15000,"Low")} -> Low | V14: =IF(K14>=50000,"VH",IF(K14>=30000,"High",IF(K14>=15000,"medium","Low"))) -> Low | W14: =IF(AND(Patient_Data!K14>40000,Patient_Data!L14="Pending"),"high Financial Risk","Normal") -> Normal | X14: =IF(AND(K14>30000,OR(E14="Cardiology",E14="Orthopedics")),"MR","No Review") -> No Review
A15: P1014 | B15: Ishita Gupta | C15: 42 | D15: Female | E15: Dermatology | F15: Psoriasis | G15: 46061 | H15: 46065 | I15: Dr Thomas | J15: Private Insurance | K15: 18000 | L15: Paid | M15: 4 | N15: =IF(L15="Pending","follow Up","No Action") -> No Action | O15: =IF(K15>40000,"high Bill","Normal Bill") -> Normal Bill | P15: =IF(C15>=60,"Senior Citizen","Non- Senior") -> Non- Senior | Q15: =IF(AND(K15>40000,M15>5),"High Billing Case","Not a High Billing Case") -> Not a High Billing Case | R15: =IF(AND(Patient_Data!L15="Pending",Patient_Data!K15>30000),"Urgent Patient Follow-up","Follow-up not Required") -> Follow-up not Required | S15: =IF(OR(Patient_Data!E15="Cardiology",Patient_Data!E15="Neurology"),"Priority Dept","RegularDept") -> RegularDept | T15: =IF(NOT(Patient_Data!L15="pending"),"Payment Completed","Payment Pending") -> Payment Completed | U15: {=_xlfn.SWITCH(TRUE,K15>=50000,"VH",K15>=30000,"High",K15>=15000,"Medium",K15<15000,"Low")} -> Medium | V15: =IF(K15>=50000,"VH",IF(K15>=30000,"High",IF(K15>=15000,"medium","Low"))) -> medium | W15: =IF(AND(Patient_Data!K15>40000,Patient_Data!L15="Pending"),"high Financial Risk","Normal") -> Normal | X15: =IF(AND(K15>30000,OR(E15="Cardiology",E15="Orthopedics")),"MR","No Review") -> No Review
A16: P1015 | B16: Manish Yadav | C16: 69 | D16: Male | E16: Cardiology | F16: Heart Disease | G16: 46063 | H16: 46073 | I16: Dr Rao | J16: Government | K16: 72000 | L16: Pending | M16: 10 | N16: =IF(L16="Pending","follow Up","No Action") -> follow Up | O16: =IF(K16>40000,"high Bill","Normal Bill") -> high Bill | P16: =IF(C16>=60,"Senior Citizen","Non- Senior") -> Senior Citizen | Q16: =IF(AND(K16>40000,M16>5),"High Billing Case","Not a High Billing Case") -> High Billing Case | R16: =IF(AND(Patient_Data!L16="Pending",Patient_Data!K16>30000),"Urgent Patient Follow-up","Follow-up not Required") -> Urgent Patient Follow-up | S16: =IF(OR(Patient_Data!E16="Cardiology",Patient_Data!E16="Neurology"),"Priority Dept","RegularDept") -> Priority Dept | T16: =IF(NOT(Patient_Data!L16="pending"),"Payment Completed","Payment Pending") -> Payment Pending | U16: {=_xlfn.SWITCH(TRUE,K16>=50000,"VH",K16>=30000,"High",K16>=15000,"Medium",K16<15000,"Low")} -> VH | V16: =IF(K16>=50000,"VH",IF(K16>=30000,"High",IF(K16>=15000,"medium","Low"))) -> VH | W16: =IF(AND(Patient_Data!K16>40000,Patient_Data!L16="Pending"),"high Financial Risk","Normal") -> high Financial Risk | X16: =IF(AND(K16>30000,OR(E16="Cardiology",E16="Orthopedics")),"MR","No Review") -> MR
A17: P1016 | B17: Neha Joshi | C17: 29 | D17: Female | E17: General Medicine | F17: Diabetes | G17: 46065 | H17: 46068 | I17: Dr Singh | J17: Self Pay | K17: 10500 | L17: Paid | M17: 3 | N17: =IF(L17="Pending","follow Up","No Action") -> No Action | O17: =IF(K17>40000,"high Bill","Normal Bill") -> Normal Bill | P17: =IF(C17>=60,"Senior Citizen","Non- Senior") -> Non- Senior | Q17: =IF(AND(K17>40000,M17>5),"High Billing Case","Not a High Billing Case") -> Not a High Billing Case | R17: =IF(AND(Patient_Data!L17="Pending",Patient_Data!K17>30000),"Urgent Patient Follow-up","Follow-up not Required") -> Follow-up not Required | S17: =IF(OR(Patient_Data!E17="Cardiology",Patient_Data!E17="Neurology"),"Priority Dept","RegularDept") -> RegularDept | T17: =IF(NOT(Patient_Data!L17="pending"),"Payment Completed","Payment Pending") -> Payment Completed | U17: {=_xlfn.SWITCH(TRUE,K17>=50000,"VH",K17>=30000,"High",K17>=15000,"Medium",K17<15000,"Low")} -> Low | V17: =IF(K17>=50000,"VH",IF(K17>=30000,"High",IF(K17>=15000,"medium","Low"))) -> Low | W17: =IF(AND(Patient_Data!K17>40000,Patient_Data!L17="Pending"),"high Financial Risk","Normal") -> Normal | X17: =IF(AND(K17>30000,OR(E17="Cardiology",E17="Orthopedics")),"MR","No Review") -> No Review
A18: P1017 | B18: Rahul Bose | C18: 58 | D18: Male | E18: Neurology | F18: Migraine | G18: 46068 | H18: 46071 | I18: Dr Khan | J18: Private Insurance | K18: 17500 | L18: Paid | M18: 3 | N18: =IF(L18="Pending","follow Up","No Action") -> No Action | O18: =IF(K18>40000,"high Bill","Normal Bill") -> Normal Bill | P18: =IF(C18>=60,"Senior Citizen","Non- Senior") -> Non- Senior | Q18: =IF(AND(K18>40000,M18>5),"High Billing Case","Not a High Billing Case") -> Not a High Billing Case | R18: =IF(AND(Patient_Data!L18="Pending",Patient_Data!K18>30000),"Urgent Patient Follow-up","Follow-up not Required") -> Follow-up not Required | S18: =IF(OR(Patient_Data!E18="Cardiology",Patient_Data!E18="Neurology"),"Priority Dept","RegularDept") -> Priority Dept | T18: =IF(NOT(Patient_Data!L18="pending"),"Payment Completed","Payment Pending") -> Payment Completed | U18: {=_xlfn.SWITCH(TRUE,K18>=50000,"VH",K18>=30000,"High",K18>=15000,"Medium",K18<15000,"Low")} -> Medium | V18: =IF(K18>=50000,"VH",IF(K18>=30000,"High",IF(K18>=15000,"medium","Low"))) -> medium | W18: =IF(AND(Patient_Data!K18>40000,Patient_Data!L18="Pending"),"high Financial Risk","Normal") -> Normal | X18: =IF(AND(K18>30000,OR(E18="Cardiology",E18="Orthopedics")),"MR","No Review") -> No Review
A19: P1018 | B19: Simran Kaur | C19: 33 | D19: Female | E19: Orthopedics | F19: Fracture | G19: 46070 | H19: 46078 | I19: Dr Mehta | J19: Government | K19: 45000 | L19: Paid | M19: 8 | N19: =IF(L19="Pending","follow Up","No Action") -> No Action | O19: =IF(K19>40000,"high Bill","Normal Bill") -> high Bill | P19: =IF(C19>=60,"Senior Citizen","Non- Senior") -> Non- Senior | Q19: =IF(AND(K19>40000,M19>5),"High Billing Case","Not a High Billing Case") -> High Billing Case | R19: =IF(AND(Patient_Data!L19="Pending",Patient_Data!K19>30000),"Urgent Patient Follow-up","Follow-up not Required") -> Follow-up not Required | S19: =IF(OR(Patient_Data!E19="Cardiology",Patient_Data!E19="Neurology"),"Priority Dept","RegularDept") -> RegularDept | T19: =IF(NOT(Patient_Data!L19="pending"),"Payment Completed","Payment Pending") -> Payment Completed | U19: {=_xlfn.SWITCH(TRUE,K19>=50000,"VH",K19>=30000,"High",K19>=15000,"Medium",K19<15000,"Low")} -> High | V19: =IF(K19>=50000,"VH",IF(K19>=30000,"High",IF(K19>=15000,"medium","Low"))) -> High | W19: =IF(AND(Patient_Data!K19>40000,Patient_Data!L19="Pending"),"high Financial Risk","Normal") -> Normal | X19: =IF(AND(K19>30000,OR(E19="Cardiology",E19="Orthopedics")),"MR","No Review") -> MR
A20: P1019 | B20: Varun Kapoor | C20: 47 | D20: Male | E20: Dermatology | F20: Skin Allergy | G20: 46073 | H20: 46075 | I20: Dr Thomas | J20: Self Pay | K20: 8000 | L20: Pending | M20: 2 | N20: =IF(L20="Pending","follow Up","No Action") -> follow Up | O20: =IF(K20>40000,"high Bill","Normal Bill") -> Normal Bill | P20: =IF(C20>=60,"Senior Citizen","Non- Senior") -> Non- Senior | Q20: =IF(AND(K20>40000,M20>5),"High Billing Case","Not a High Billing Case") -> Not a High Billing Case | R20: =IF(AND(Patient_Data!L20="Pending",Patient_Data!K20>30000),"Urgent Patient Follow-up","Follow-up not Required") -> Follow-up not Required | S20: =IF(OR(Patient_Data!E20="Cardiology",Patient_Data!E20="Neurology"),"Priority Dept","RegularDept") -> RegularDept | T20: =IF(NOT(Patient_Data!L20="pending"),"Payment Completed","Payment Pending") -> Payment Pending | U20: {=_xlfn.SWITCH(TRUE,K20>=50000,"VH",K20>=30000,"High",K20>=15000,"Medium",K20<15000,"Low")} -> Low | V20: =IF(K20>=50000,"VH",IF(K20>=30000,"High",IF(K20>=15000,"medium","Low"))) -> Low | W20: =IF(AND(Patient_Data!K20>40000,Patient_Data!L20="Pending"),"high Financial Risk","Normal") -> Normal | X20: =IF(AND(K20>30000,OR(E20="Cardiology",E20="Orthopedics")),"MR","No Review") -> No Review
A21: P1020 | B21: Pooja Agarwal | C21: 55 | D21: Female | E21: Cardiology | F21: Chest Pain | G21: 46075 | H21: 46080 | I21: Dr Rao | J21: Private Insurance | K21: 31000 | L21: Paid | M21: 5 | N21: =IF(L21="Pending","follow Up","No Action") -> No Action | O21: =IF(K21>40000,"high Bill","Normal Bill") -> Normal Bill | P21: =IF(C21>=60,"Senior Citizen","Non- Senior") -> Non- Senior | Q21: =IF(AND(K21>40000,M21>5),"High Billing Case","Not a High Billing Case") -> Not a High Billing Case | R21: =IF(AND(Patient_Data!L21="Pending",Patient_Data!K21>30000),"Urgent Patient Follow-up","Follow-up not Required") -> Follow-up not Required | S21: =IF(OR(Patient_Data!E21="Cardiology",Patient_Data!E21="Neurology"),"Priority Dept","RegularDept") -> Priority Dept | T21: =IF(NOT(Patient_Data!L21="pending"),"Payment Completed","Payment Pending") -> Payment Completed | U21: {=_xlfn.SWITCH(TRUE,K21>=50000,"VH",K21>=30000,"High",K21>=15000,"Medium",K21<15000,"Low")} -> High | V21: =IF(K21>=50000,"VH",IF(K21>=30000,"High",IF(K21>=15000,"medium","Low"))) -> High | W21: =IF(AND(Patient_Data!K21>40000,Patient_Data!L21="Pending"),"high Financial Risk","Normal") -> Normal | X21: =IF(AND(K21>30000,OR(E21="Cardiology",E21="Orthopedics")),"MR","No Review") -> MR
... A41: P1040 | B41: Sonali Shah | C41: 50 | D41: Female | E41: Cardiology | F41: Heart Disease | G41: 46134 | H41: 46144 | I41: Dr Rao | J41: Private Insurance | K41: 69000 | L41: Paid | M41: 10 | N41: =IF(L41="Pending","follow Up","No Action") -> No Action | O41: =IF(K41>40000,"high Bill","Normal Bill") -> high Bill | P41: =IF(C41>=60,"Senior Citizen","Non- Senior") -> Non- Senior | Q41: =IF(AND(K41>40000,M41>5),"High Billing Case","Not a High Billing Case") -> High Billing Case | R41: =IF(AND(Patient_Data!L41="Pending",Patient_Data!K41>30000),"Urgent Patient Follow-up","Follow-up not Required") -> Follow-up not Required | S41: =IF(OR(Patient_Data!E41="Cardiology",Patient_Data!E41="Neurology"),"Priority Dept","RegularDept") -> Priority Dept | T41: =IF(NOT(Patient_Data!L41="pending"),"Payment Completed","Payment Pending") -> Payment Completed | U41: {=_xlfn.SWITCH(TRUE,K41>=50000,"VH",K41>=30000,"High",K41>=15000,"Medium",K41<15000,"Low")} -> VH | V41: =IF(K41>=50000,"VH",IF(K41>=30000,"High",IF(K41>=15000,"medium","Low"))) -> VH | W41: =IF(AND(Patient_Data!K41>40000,Patient_Data!L41="Pending"),"high Financial Risk","Normal") -> Normal | X41: =IF(AND(K41>30000,OR(E41="Cardiology",E41="Orthopedics")),"MR","No Review") -> MR
K44: Department
K45: Dermatology
E47: Find total hospital billing. | G47: =SUM(Bills) -> 1019500
E48: Find total billing for Cardialogy department. | G48: =SUMIF(Department,"Cardiology",Bills) -> 443500
E49: Count patients in Dermatology department. | G49: =COUNTIF(Department,"Dermatology") -> 7 | K49: =DSUM(A2:X41,11,K44:K45) -> 0
E50: Find average bill by Neurology department. | G50: =AVERAGEIF(Department,"Neurology",Bills) -> 25571.429 | K50: =DSUM(A2:X41,11,K44:K45) -> 0
E51: Find total billing for Government insurance. | G51: =SUMIF(J2:J41,"Government",Bills) -> 499500
E52: Count patients with Pending payments. | G52: =COUNTIF(L2:L41,"Pending") -> 10
E53: Find total Pending billing. | G53: =SUMIF(L2:L41,"Pending",Bills) -> 344500
E54: Find total billing for Cardiology + Government insurance. | H54: =SUMIFS(Bills,Department,"Cardiology",J2:J41,"Government") -> 275500
E55: Count Cardiology patients with Pending payment. | H55: =COUNTIFS(Department,"Cardiology",L2:L41,"Pending") -> 4
E56: Find average bill for patients with Private Insurance. | H56: =AVERAGEIF(J2:J41,"Private Insurance",Bills) -> 25766.667
E57: Count patients with bills above ₹40,000. | H57: =COUNTIF(Bills,">40000") -> 9
E58: Find total billing for patients with bills above ₹40,000. | H58: =SUMIF(Bills,">40000",Bills) -> 508000
E59: Count patients staying more than 5 days. | H59: =COUNTIF(M2:M41,">5") -> 11
E60: Find total billing for patients staying more than 5 days. | H60: =SUMIF(M2:M41,">5",Bills) -> 582000
E61: Find total billing for Cardiology patients staying more than 5 days. | H61: =SUMIFS(Bills,Department,"Cardiology",M2:M41,">5") -> 320000
E62: Find average length of stay for Pending patients. | H62: =AVERAGEIF(L2:L41,"pending",M2:M41) -> 5.8
...

Sheet Questions
A1: Question:
A2: Create a new column called Payment Alert.
A3: If Payment Status is Pending, display "Follow Up", otherwise display "No Action".
A5: Create a column called Bill Category.
A6: Bill > ₹40,000 → High Bill
A7: Otherwise → Normal Bill
A9: Create a column called Age Category.
A10: If Age is 60 or above:Senior Citizen
A11: Otherwise:Non-Senior
A13: A patient is a High Billing Case if:
A14: Bill Amount > ₹40,000
A15: AND
... A28: Payment Completed Otherwise:Payment Pending
A30: create a bill category | B30: Bill Amount | C30: Category
B31: ≥ ₹50,000 | C31: Very High
B32: ≥ ₹30,000 | C32: High
B33: ≥ ₹15,000 | C33: Medium
B34: < ₹15,000 | C34: Low
A37: If:
A38: Bill > ₹40,000
A39: AND Payment = Pending
A40: Output:High Financial Risk Otherwise:Normal
A42: A patient needs management review if:
A44: They are from Cardiology OR Orthopedics,
A45: AND their bill is greater than ₹30,000. then MR, NO Review

Sheet Answers
A1: # | B1: Analysis | C1: Function | D1: Answer
A2: 1 | B2: Total hospital billing | C2: SUM | D2: 1019500
A3: 2 | B3: Cardiology billing | C3: SUMIF | D3: 443500
A4: 2 | B4: Dermatology billing | C4: SUMIF | D4: 89500
A5: 2 | B5: General Medicine billing | C5: SUMIF | D5: 77500
A6: 2 | B6: Neurology billing | C6: SUMIF | D6: 179000
A7: 2 | B7: Orthopedics billing | C7: SUMIF | D7: 230000
A8: 3 | B8: Cardiology patients | C8: COUNTIF | D8: 10
A9: 3 | B9: Dermatology patients | C9: COUNTIF | D9: 7
A10: 3 | B10: General Medicine patients | C10: COUNTIF | D10: 8
A11: 3 | B11: Neurology patients | C11: COUNTIF | D11: 7
A12: 3 | B12: Orthopedics patients | C12: COUNTIF | D12: 8
A13: 4 | B13: Avg Cardiology bill | C13: AVERAGEIF | D13: 44350
... A28: 15 | B28: Cardiology + stay > 5 days | C28: SUMIFS | D28: 320000
A29: 16 | B29: Avg stay of Pending patients | C29: AVERAGEIF | D29: 5.8 days
A30: 17 | B30: Maximum Cardiology bill | C30: MAXIFS | D30: 76000
A31: 18 | B31: Minimum Orthopedics bill | C31: MINIFS | D31: 12500
